Workbook

Sheet Landscape Data
A1: Publication Number | B1: Title | C1: Publication Date | D1: Year | E1: Country Code | F1: Company | G1: Category | H1: Current Assignee First | I1: Citing Patent Count
A2: US12670263 | B2: Large language model-based vulnerability remediation action descriptions | C2: 2026-06-30 | D2: 2026 | E2: US | F2: Palo Alto Networks | G2: Vulnerability Management & Remediation | H2: PALO ALTO NETWORKS INC | I2: 0
A3: US12670274 | B3: Dynamically securing operations in agentic artificial intelligence models | C3: 2026-06-30 | D3: 2026 | E3: US | F3: CyberArk | G3: Agentic AI Orchestration Security | H3: CYBERARK SOFTWARE LTD | I3: 0
A4: US12671676 | B4: Fast policy matching with runtime signature update | C4: 2026-06-30 | D4: 2026 | E4: US | F4: Palo Alto Networks | G4: Malware & Ransomware Defense | H4: PALO ALTO NETWORKS INC | I4: 0
A5: US12671699 | B5: Campaign intelligence and visualization for combating cyberattacks | C5: 2026-06-30 | D5: 2026 | E5: US | F5: Microsoft | G5: SecOps Automation & Incident Response | H5: MICROSOFT TECH LICENSING LLC | I5: 0
A6: US20260178746 | B6: Identifying vulnerabilities in binary files using a code signature | C6: 2026-06-25 | D6: 2026 | E6: US | F6: Palo Alto Networks | G6: Vulnerability Management & Remediation | H6: PALO ALTO NETWORKS INC | I6: 0
A7: US20260181022 | B7: Cloud dynamic endpoint group | C7: 2026-06-25 | D7: 2026 | E7: US | F7: Palo Alto Networks | G7: Endpoint & Device Security | H7: PALO ALTO NETWORKS INC | I7: 0
A8: US20260181024 | B8: Consolidated alert remediation using large language models and graph structures | C8: 2026-06-25 | D8: 2026 | E8: US | F8: Palo Alto Networks | G8: LLM & Generative AI Security | H8: PALO ALTO NETWORKS INC | I8: 0
A9: WO2026131200A1 | B9: Grouped ransomware detection in data storage systems | C9: 2026-06-25 | D9: 2026 | E9: WO | F9: IBM | G9: Malware & Ransomware Defense | H9: IBM DEUTSCHLAND GMBH | I9: 0
A10: EP4762469A1 | B10: Artificial intelligence security engine in a security management system | C10: 2026-06-24 | D10: 2026 | E10: EP | F10: Microsoft | G10: SecOps Automation & Incident Response | H10: MICROSOFT TECH LICENSING LLC | I10: 0
A11: EP4762706A2 | B11: Cyber security systems and methods | C11: 2026-06-24 | D11: 2026 | E11: EP | F11: Palo Alto Networks | G11: Identity & Access Management | H11: PALO ALTO NETWORKS INC | I11: 0
A12: EP4764918A2 | B12: Context informed abnormal endpoint behavior detection | C12: 2026-06-24 | D12: 2026 | E12: EP | F12: Palo Alto Networks | G12: AI Threat & Anomaly Detection | H12: PALO ALTO NETWORKS INC | I12: 0
A13: EP4765755A2 | B13: Machine learning time series anomaly detection | C13: 2026-06-24 | D13: 2026 | E13: EP | F13: Google (Alphabet) | G13: AI Threat & Anomaly Detection | H13: GOOGLE LLC | I13: 0
... A607: US11558484 | B607: Systems and methods for secure peer-to-peer caching | C607: 2023-01-17 | D607: 2023 | E607: US | F607: Citrix | G607: Endpoint & Device Security | H607: CITRIX SYS INC | I607: 0

Sheet Summary Pivots
A1: Patents by Category | B1: Count
A2: AI Threat & Anomaly Detection | B2: =COUNTIF('Landscape Data'!G2:G607,A2) -> 118
A3: LLM & Generative AI Security | B3: =COUNTIF('Landscape Data'!G2:G607,A3) -> 74
A4: SecOps Automation & Incident Response | B4: =COUNTIF('Landscape Data'!G2:G607,A4) -> 73
A5: Identity & Access Management | B5: =COUNTIF('Landscape Data'!G2:G607,A5) -> 72
A6: Vulnerability Management & Remediation | B6: =COUNTIF('Landscape Data'!G2:G607,A6) -> 62
A7: Malware & Ransomware Defense | B7: =COUNTIF('Landscape Data'!G2:G607,A7) -> 57
A8: Network & Traffic Security | B8: =COUNTIF('Landscape Data'!G2:G607,A8) -> 51
A9: Cloud & Container Security | B9: =COUNTIF('Landscape Data'!G2:G607,A9) -> 47
A10: Endpoint & Device Security | B10: =COUNTIF('Landscape Data'!G2:G607,A10) -> 45
A11: Agentic AI Orchestration Security | B11: =COUNTIF('Landscape Data'!G2:G607,A11) -> 7
A12: Total | B12: =SUM(B2:B11) -> 606
A14: Patents by Company (Top 10) | B14: Count
A15: Microsoft | B15: =COUNTIF('Landscape Data'!F2:F607,A15) -> 154
A16: Cisco (incl. Splunk) | B16: =COUNTIF('Landscape Data'!F2:F607,A16) -> 133
A17: Palo Alto Networks | B17: =COUNTIF('Landscape Data'!F2:F607,A17) -> 102
A18: CrowdStrike | B18: =COUNTIF('Landscape Data'!F2:F607,A18) -> 50
A19: Fortinet | B19: =COUNTIF('Landscape Data'!F2:F607,A19) -> 38
A20: Google (Alphabet) | B20: =COUNTIF('Landscape Data'!F2:F607,A20) -> 31
A21: Samsung | B21: =COUNTIF('Landscape Data'!F2:F607,A21) -> 25
A22: CyberArk | B22: =COUNTIF('Landscape Data'!F2:F607,A22) -> 19
A23: Citrix | B23: =COUNTIF('Landscape Data'!F2:F607,A23) -> 17
A24: IBM | B24: =COUNTIF('Landscape Data'!F2:F607,A24) -> 11
A26: Patents by Publication Year | B26: Count
A27: 2023 | B27: =COUNTIF('Landscape Data'!D2:D607,2023) -> 60
A28: 2024 | B28: =COUNTIF('Landscape Data'!D2:D607,2024) -> 87
A29: 2025 | B29: =COUNTIF('Landscape Data'!D2:D607,2025) -> 222
A30: 2026 | B30: =COUNTIF('Landscape Data'!D2:D607,2026) -> 237
A33: Category x Year | B33: 2023 | C33: 2024 | D33: 2025 | E33: 2026
A34: AI Threat & Anomaly Detection | B34: =COUNTIFS('Landscape Data'!G$2:G$607,$A34,'Landscape Data'!D$2:D$607,2023) -> 16 | C34: =COUNTIFS('Landscape Data'!G$2:G$607,$A34,'Landscape Data'!D$2:D$607,2024) -> 21 | D34: =COUNTIFS('Landscape Data'!G$2:G$607,$A34,'Landscape Data'!D$2:D$607,2025) -> 40 | E34: =COUNTIFS('Landscape Data'!G$2:G$607,$A34,'Landscape Data'!D$2:D$607,2026) -> 41
A35: LLM & Generative AI Security | B35: =COUNTIFS('Landscape Data'!G$2:G$607,$A35,'Landscape Data'!D$2:D$607,2023) -> 0 | C35: =COUNTIFS('Landscape Data'!G$2:G$607,$A35,'Landscape Data'!D$2:D$607,2024) -> 1 | D35: =COUNTIFS('Landscape Data'!G$2:G$607,$A35,'Landscape Data'!D$2:D$607,2025) -> 34 | E35: =COUNTIFS('Landscape Data'!G$2:G$607,$A35,'Landscape Data'!D$2:D$607,2026) -> 39
A36: SecOps Automation & Incident Response | B36: =COUNTIFS('Landscape Data'!G$2:G$607,$A36,'Landscape Data'!D$2:D$607,2023) -> 7 | C36: =COUNTIFS('Landscape Data'!G$2:G$607,$A36,'Landscape Data'!D$2:D$607,2024) -> 13 | D36: =COUNTIFS('Landscape Data'!G$2:G$607,$A36,'Landscape Data'!D$2:D$607,2025) -> 28 | E36: =COUNTIFS('Landscape Data'!G$2:G$607,$A36,'Landscape Data'!D$2:D$607,2026) -> 25
A37: Identity & Access Management | B37: =COUNTIFS('Landscape Data'!G$2:G$607,$A37,'Landscape Data'!D$2:D$607,2023) -> 14 | C37: =COUNTIFS('Landscape Data'!G$2:G$607,$A37,'Landscape Data'!D$2:D$607,2024) -> 9 | D37: =COUNTIFS('Landscape Data'!G$2:G$607,$A37,'Landscape Data'!D$2:D$607,2025) -> 24 | E37: =COUNTIFS('Landscape Data'!G$2:G$607,$A37,'Landscape Data'!D$2:D$607,2026) -> 25
A38: Vulnerability Management & Remediation | B38: =COUNTIFS('Landscape Data'!G$2:G$607,$A38,'Landscape Data'!D$2:D$607,2023) -> 9 | C38: =COUNTIFS('Landscape Data'!G$2:G$607,$A38,'Landscape Data'!D$2:D$607,2024) -> 8 | D38: =COUNTIFS('Landscape Data'!G$2:G$607,$A38,'Landscape Data'!D$2:D$607,2025) -> 18 | E38: =COUNTIFS('Landscape Data'!G$2:G$607,$A38,'Landscape Data'!D$2:D$607,2026) -> 27
A39: Malware & Ransomware Defense | B39: =COUNTIFS('Landscape Data'!G$2:G$607,$A39,'Landscape Data'!D$2:D$607,2023) -> 2 | C39: =COUNTIFS('Landscape Data'!G$2:G$607,$A39,'Landscape Data'!D$2:D$607,2024) -> 10 | D39: =COUNTIFS('Landscape Data'!G$2:G$607,$A39,'Landscape Data'!D$2:D$607,2025) -> 22 | E39: =COUNTIFS('Landscape Data'!G$2:G$607,$A39,'Landscape Data'!D$2:D$607,2026) -> 23
A40: Network & Traffic Security | B40: =COUNTIFS('Landscape Data'!G$2:G$607,$A40,'Landscape Data'!D$2:D$607,2023) -> 3 | C40: =COUNTIFS('Landscape Data'!G$2:G$607,$A40,'Landscape Data'!D$2:D$607,2024) -> 7 | D40: =COUNTIFS('Landscape Data'!G$2:G$607,$A40,'Landscape Data'!D$2:D$607,2025) -> 15 | E40: =COUNTIFS('Landscape Data'!G$2:G$607,$A40,'Landscape Data'!D$2:D$607,2026) -> 26
A41: Cloud & Container Security | B41: =COUNTIFS('Landscape Data'!G$2:G$607,$A41,'Landscape Data'!D$2:D$607,2023) -> 4 | C41: =COUNTIFS('Landscape Data'!G$2:G$607,$A41,'Landscape Data'!D$2:D$607,2024) -> 8 | D41: =COUNTIFS('Landscape Data'!G$2:G$607,$A41,'Landscape Data'!D$2:D$607,2025) -> 18 | E41: =COUNTIFS('Landscape Data'!G$2:G$607,$A41,'Landscape Data'!D$2:D$607,2026) -> 17
A42: Endpoint & Device Security | B42: =COUNTIFS('Landscape Data'!G$2:G$607,$A42,'Landscape Data'!D$2:D$607,2023) -> 5 | C42: =COUNTIFS('Landscape Data'!G$2:G$607,$A42,'Landscape Data'!D$2:D$607,2024) -> 10 | D42: =COUNTIFS('Landscape Data'!G$2:G$607,$A42,'Landscape Data'!D$2:D$607,2025) -> 19 | E42: =COUNTIFS('Landscape Data'!G$2:G$607,$A42,'Landscape Data'!D$2:D$607,2026) -> 11
A43: Agentic AI Orchestration Security | B43: =COUNTIFS('Landscape Data'!G$2:G$607,$A43,'Landscape Data'!D$2:D$607,2023) -> 0 | C43: =COUNTIFS('Landscape Data'!G$2:G$607,$A43,'Landscape Data'!D$2:D$607,2024) -> 0 | D43: =COUNTIFS('Landscape Data'!G$2:G$607,$A43,'Landscape Data'!D$2:D$607,2025) -> 4 | E43: =COUNTIFS('Landscape Data'!G$2:G$607,$A43,'Landscape Data'!D$2:D$607,2026) -> 3
A46: Company x Category (Top 6) | B46: AI Threat & Anomaly Detection | C46: LLM & Generative AI Security | D46: SecOps Automation & Incident Response | E46: Identity & Access Management | F46: Vulnerability Management & Remediation | G46: Malware & Ransomware Defense | H46: Network & Traffic Security | I46: Cloud & Container Security | J46: Endpoint & Device Security | K46: Agentic AI Orchestration Security
...

Sheet Excluded Records
A1: Publication Number | B1: Title | C1: Publication Date | D1: Year | E1: Country Code | F1: Company | G1: Category | H1: Current Assignee First | I1: Citing Patent Count
A2: US12670170 | B2: Search recovery using a shared storage system following a failed search peer | C2: 2026-06-30 | D2: 2026 | E2: US | F2: Cisco (incl. Splunk) | G2: Irrelevant / Out of Scope | H2: CISCO TECH INC | I2: 0
A3: US12670434 | B3: Multiple instance learning models for cybersecurity using JavaScript object notation (JSON) training data | C3: 2026-06-30 | D3: 2026 | E3: US | F3: Cisco (incl. Splunk) | G3: Irrelevant / Out of Scope | H3: CISCO TECH INC | I3: 0
A4: US12671691 | B4: Mode-based user activity monitoring in web browser | C4: 2026-06-30 | D4: 2026 | E4: US | F4: Palo Alto Networks | G4: Irrelevant / Out of Scope | H4: PALO ALTO NETWORKS INC | I4: 0
A5: US20260178555 | B5: Semantic search for retrieval-augmented generation | C5: 2026-06-25 | D5: 2026 | E5: US | F5: Microsoft | G5: Irrelevant / Out of Scope | H5: MICROSOFT TECH LICENSING LLC | I5: 0
A6: US20260178745 | B6: Orchestrated execution of code by a cloud-based data intake and query system | C6: 2026-06-25 | D6: 2026 | E6: US | F6: Cisco (incl. Splunk) | G6: Irrelevant / Out of Scope | H6: CISCO TECH INC | I6: 0
A7: CN117793251B | B7: Customer service call quality inspection method and device, computer equipment and storage medium | C7: 2026-06-23 | D7: 2026 | E7: CN | F7: Ping An | G7: Irrelevant / Out of Scope | H7: PING AN PROPERTY & CASUALTY INSURANCE CO OF CHINA LTD | I7: 0
A8: US20260172425 | B8: Profile grants for granting permissions for tool access | C8: 2026-06-18 | D8: 2026 | E8: US | F8: Zilla Security Inc | G8: Irrelevant / Out of Scope | H8: ZILLA SECURITY INC | I8: 0
A9: EP4760601A1 | B9: Memory efficient machine learning model training | C9: 2026-06-17 | D9: 2026 | E9: EP | F9: Microsoft | G9: Irrelevant / Out of Scope | H9: MICROSOFT TECH LICENSING LLC | I9: 0
A10: US12657197 | B10: Three-dimensional drill-down data visualization in extended reality environment | C10: 2026-06-16 | D10: 2026 | E10: US | F10: Cisco (incl. Splunk) | G10: Irrelevant / Out of Scope | H10: CISCO TECH INC | I10: 0
A11: US12657223 | B11: Systems and methods for detection of beaconing through the deployment of machine learning models | C11: 2026-06-16 | D11: 2026 | E11: US | F11: Cisco (incl. Splunk) | G11: Irrelevant / Out of Scope | H11: CISCO TECH INC | I11: 0
A12: US12657455 | B12: Computer implemented pre-processing method and system for facilitating machine learning signal classes separability, and, non-transitory computer readable storage medium | C12: 2026-06-16 | D12: 2026 | E12: US | F12: Samsung | G12: Irrelevant / Out of Scope | H12: SAMSUNG ELTNC DA AMAZONIA LTDA | I12: 0
A13: US12659228 | B13: Using large language models to recommend and validate asset and/or cloud configurations | C13: 2026-06-16 | D13: 2026 | E13: US | F13: CrowdStrike | G13: Irrelevant / Out of Scope | H13: CROWDSTRIKE INC | I13: 0
... A429: US11546361 | B429: Method and apparatus for organizing and detecting swarms in a network | C429: 2023-01-03 | D429: 2023 | E429: US | F429: Samsung | G429: Irrelevant / Out of Scope | H429: SAMSUNG ELTNC CO LTD | I429: 5
